<?xml version="1.0" ?>
<robot name="assembly">

<material name="silver">
  <color rgba="0.700 0.700 0.700 1.000"/>
</material>

<link name="base_link">
  <inertial>
    <origin rpy="0 0 1.57079632679" xyz="0.0 0.25 0.01"/>
    <mass value="0.616"/>
    <inertia ixx="0.0146" ixy="0.0" ixz="0.0" iyy="0.002" iyz="0.0" izz="0.017"/>
  </inertial>
  <visual>
    <origin rpy="0 0 0" xyz="0 0 0"/>
    <geometry>
      <mesh filename="meshes/base_link.stl" scale="0.001 0.001 0.001"/>
    </geometry>
    <material name="silver"/>
    <material/>
  </visual>
  <collision>
    <origin rpy="0 0 0" xyz="0 0 0"/>
    <geometry>
      <mesh filename="meshes/base_link.stl" scale="0.001 0.001 0.001"/>
    </geometry>
  </collision>
</link>

<link name="leg_fl_v61body_leg_fl1">
  <inertial>
    <origin rpy="0 0 0" xyz="1.3863910020006642e-14 0.006648607737863521 -0.014708098125756902"/>
    <mass value="0.06"/>
    <inertia ixx="0.000017" ixy="0" ixz="0" iyy="0.000067" iyz="0.0000031" izz="0.000059"/>
  </inertial>
  <visual>
    <origin rpy="0 0 0" xyz="0.079 -0.298 -0.0"/>
    <geometry>
      <mesh filename="meshes/leg_fl_v61body_leg_fl1.stl" scale="0.001 0.001 0.001"/>
    </geometry>
    <material name="silver"/>
    <material/>
  </visual>
  <collision>
    <origin rpy="0 0 0" xyz="0.079 -0.298 -0.0"/>
    <geometry>
      <mesh filename="meshes/leg_fl_v61body_leg_fl1.stl" scale="0.001 0.001 0.001"/>
    </geometry>
  </collision>
</link>

<link name="leg_fr_v81body_leg_fr1">
  <inertial>
    <origin rpy="0 0 0" xyz="1.3697376566312869e-14 0.006648607737863521 -0.014708098125756902"/>
    <mass value="0.06"/>
    <inertia ixx="0.000017" ixy="0" ixz="0" iyy="0.000067" iyz="0.0000031" izz="0.000059"/>
  </inertial>
  <visual>
    <origin rpy="0 0 0" xyz="-0.079 -0.298 -0.0"/>
    <geometry>
      <mesh filename="meshes/leg_fr_v81body_leg_fr1.stl" scale="0.001 0.001 0.001"/>
    </geometry>
    <material name="silver"/>
    <material/>
  </visual>
  <collision>
    <origin rpy="0 0 0" xyz="-0.079 -0.298 -0.0"/>
    <geometry>
      <mesh filename="meshes/leg_fr_v81body_leg_fr1.stl" scale="0.001 0.001 0.001"/>
    </geometry>
  </collision>
</link>

<link name="leg_bl_v21body_leg_bl1">
  <inertial>
    <origin rpy="0 0 0" xyz="-1.3766765505351941e-14 -0.006648607737863604 -0.01470809812575689"/>
    <mass value="0.06"/>
    <inertia ixx="0.000017" ixy="0" ixz="0" iyy="0.000067" iyz="-0.0000031" izz="0.000059"/>
  </inertial>
  <visual>
    <origin rpy="0 0 0" xyz="0.079 -0.202 -0.0"/>
    <geometry>
      <mesh filename="meshes/leg_bl_v21body_leg_bl1.stl" scale="0.001 0.001 0.001"/>
    </geometry>
    <material name="silver"/>
    <material/>
  </visual>
  <collision>
    <origin rpy="0 0 0" xyz="0.079 -0.202 -0.0"/>
    <geometry>
      <mesh filename="meshes/leg_bl_v21body_leg_bl1.stl" scale="0.001 0.001 0.001"/>
    </geometry>
  </collision>
</link>

<link name="leg_br_v21body_leg_br1">
  <inertial>
    <origin rpy="0 0 0" xyz="-1.3863910020006642e-14 -0.006648607737863632 -0.014708098125756902"/>
        <mass value="0.06"/>
    <inertia ixx="0.000017" ixy="0" ixz="0" iyy="0.000067" iyz="-0.0000031" izz="0.000059"/>
  </inertial>
  <visual>
    <origin rpy="0 0 0" xyz="-0.079 -0.202 -0.0"/>
    <geometry>
      <mesh filename="meshes/leg_br_v21body_leg_br1.stl" scale="0.001 0.001 0.001"/>
    </geometry>
    <material name="silver"/>
    <material/>
  </visual>
  <collision>
    <origin rpy="0 0 0" xyz="-0.079 -0.202 -0.0"/>
    <geometry>
      <mesh filename="meshes/leg_br_v21body_leg_br1.stl" scale="0.001 0.001 0.001"/>
    </geometry>
  </collision>
</link>



<link name="leg_fl_v61motor_1_fl1">
  <inertial>
    <origin rpy="0 0 0" xyz="-5.995204332975845e-15 0.026228618678054205 0.027782105819294068"/>
    <mass value="0.71"/>
    <inertia ixx="0.00525" ixy="0" ixz="0" iyy="0.000807" iyz="0.0000114" izz="0.00051"/>
  </inertial>
  <visual>
    <origin rpy="0 0 0" xyz="0.079 -0.305885 0.0345"/>
    <geometry>
      <mesh filename="meshes/leg_fl_v61motor_1_fl1.stl" scale="0.001 0.001 0.001"/>
    </geometry>
    <material name="silver"/>
    <material/>
  </visual>
  <collision>
    <origin rpy="0 0 0" xyz="0.079 -0.305885 0.0345"/>
    <geometry>
      <mesh filename="meshes/leg_fl_v61motor_1_fl1.stl" scale="0.001 0.001 0.001"/>
    </geometry>
  </collision>
</link>

<link name="leg_fl_v61scap_x_y_fl1">
  <inertial>
    <origin rpy="0 0 0" xyz="0.0021679930846135315 0.011009286173284172 -1.5785983631388945e-15"/>
    <mass value="0.0325"/>
    <inertia ixx="0.000014" ixy="0.00000057" ixz="0" iyy="0.000015" iyz="" izz="0.0000041"/>
  </inertial>
  <visual>
    <origin rpy="0 0 0" xyz="0.079 -0.354385 0.0075"/>
    <geometry>
      <mesh filename="meshes/leg_fl_v61scap_x_y_fl1.stl" scale="0.001 0.001 0.001"/>
    </geometry>
    <material name="silver"/>
    <material/>
  </visual>
  <collision>
    <origin rpy="0 0 0" xyz="0.079 -0.354385 0.0075"/>
    <geometry>
      <mesh filename="meshes/leg_fl_v61scap_x_y_fl1.stl" scale="0.001 0.001 0.001"/>
    </geometry>
  </collision>
</link>

<link name="leg_fl_v61motor_2_fl1">
  <inertial>
    <origin rpy="0 0 0" xyz="-0.014728950785940165 0.04199966789210802 0.0007821058192939807"/>
    <mass value="0.71"/>
    <inertia ixx="0.00087" ixy="0" ixz="-0.0000115" iyy="0.00051" iyz="0" izz="0.00051"/>
  </inertial>
  <visual>
    <origin rpy="0 0 0" xyz="0.091 -0.366385 0.0075"/>
    <geometry>
      <mesh filename="meshes/leg_fl_v61motor_2_fl1.stl" scale="0.001 0.001 0.001"/>
    </geometry>
    <material name="silver"/>
    <material/>
  </visual>
  <collision>
    <origin rpy="0 0 0" xyz="0.091 -0.366385 0.0075"/>
    <geometry>
      <mesh filename="meshes/leg_fl_v61motor_2_fl1.stl" scale="0.001 0.001 0.001"/>
    </geometry>
  </collision>
</link>

<link name="leg_fl_v61upperleg_int_fl1">
  <inertial>
    <origin rpy="0 0 0" xyz="-0.0024999999999998357 -3.321078864693128e-07 -0.10894505554394376"/>
    <mass value="0.056"/>
    <inertia ixx="0.00031" ixy="0" ixz="0" iyy="0.00029" iyz="0" izz="0.0000084"/>
  </inertial>
  <visual>
    <origin rpy="0 0 0" xyz="0.128 -0.408385 0.0075"/>
    <geometry>
      <mesh filename="meshes/leg_fl_v61upperleg_int_fl1.stl" scale="0.001 0.001 0.001"/>
    </geometry>
    <material name="silver"/>
    <material/>
  </visual>
  <collision>
    <origin rpy="0 0 0" xyz="0.128 -0.408385 0.0075"/>
    <geometry>
      <mesh filename="meshes/leg_fl_v61upperleg_int_fl1.stl" scale="0.001 0.001 0.001"/>
    </geometry>
  </collision>
</link>

<link name="leg_fl_v61link_motor_2_3_fl1">
  <inertial>
    <origin rpy="0 0 0" xyz="-0.017914510831100044 -3.321078899665153e-07 0.007534024575946553"/>
    <mass value="0.104"/>
    <inertia ixx="0.00017" ixy="0" ixz="0.0000036" iyy="0.000083" iyz="0" izz="0.00011"/>
  </inertial>
  <visual>
    <origin rpy="0 0 0" xyz="0.128 -0.408385 0.0075"/>
    <geometry>
      <mesh filename="meshes/leg_fl_v61link_motor_2_3_fl1.stl" scale="0.001 0.001 0.001"/>
    </geometry>
    <material name="silver"/>
    <material/>
  </visual>
  <collision>
    <origin rpy="0 0 0" xyz="0.128 -0.408385 0.0075"/>
    <geometry>
      <mesh filename="meshes/leg_fl_v61link_motor_2_3_fl1.stl" scale="0.001 0.001 0.001"/>
    </geometry>
  </collision>
</link>

<link name="leg_fl_v61upperleg_ext_fl1">
  <inertial>
    <origin rpy="0 0 0" xyz="-0.0025000000000000022 -3.322518468129587e-07 -0.08837314619383613"/>
    <mass value="0.067"/>
    <inertia ixx="0.00049" ixy="0.0" ixz="0" iyy="0.000462" iyz="0" izz="0.0000266"/>
  </inertial>
  <visual>
    <origin rpy="0 0 0" xyz="0.165 -0.408385 0.0075"/>
    <geometry>
      <mesh filename="meshes/leg_fl_v61upperleg_ext_fl1.stl" scale="0.001 0.001 0.001"/>
    </geometry>
    <material name="silver"/>
    <material/>
  </visual>
  <collision>
    <origin rpy="0 0 0" xyz="0.165 -0.408385 0.0075"/>
    <geometry>
      <mesh filename="meshes/leg_fl_v61upperleg_ext_fl1.stl" scale="0.001 0.001 0.001"/>
    </geometry>
  </collision>
</link>

<link name="leg_fl_v61motor_3_fl1">
  <inertial>
    <origin rpy="0 0 0" xyz="-0.02227104921405984 -3.321078793638854e-07 0.0007821058192940405"/>
    <mass value="0.71"/>
    <inertia ixx="0.00081" ixy="0" ixz="0.000001152" iyy="0.000525" iyz="0" izz="0.00051"/>
  </inertial>
  <visual>
    <origin rpy="0 0 0" xyz="0.168 -0.408385 0.0075"/>
    <geometry>
      <mesh filename="meshes/leg_fl_v61motor_3_fl1.stl" scale="0.001 0.001 0.001"/>
    </geometry>
    <material name="silver"/>
    <material/>
  </visual>
  <collision>
    <origin rpy="0 0 0" xyz="0.168 -0.408385 0.0075"/>
    <geometry>
      <mesh filename="meshes/leg_fl_v61motor_3_fl1.stl" scale="0.001 0.001 0.001"/>
    </geometry>
  </collision>
</link>

<link name="leg_fl_v61lowerleg_ext_fl1">
  <inertial>
    <origin rpy="0 0 0" xyz="0.00250000000000003 1.8038551013954685e-05 -0.08216087510741524"/>
    <mass value="0.0448"/>
    <inertia ixx="0.000154" ixy="0" ixz="0" iyy="0.00014" iyz="0.000000066" izz="0.0000066"/>
  </inertial>
  <visual>
    <origin rpy="0 0 0" xyz="0.16 -0.408385 0.2035"/>
    <geometry>
      <mesh filename="meshes/leg_fl_v61lowerleg_ext_fl1.stl" scale="0.001 0.001 0.001"/>
    </geometry>
    <material name="silver"/>
    <material/>
  </visual>
  <collision>
    <origin rpy="0 0 0" xyz="0.16 -0.408385 0.2035"/>
    <geometry>
      <mesh filename="meshes/leg_fl_v61lowerleg_ext_fl1.stl" scale="0.001 0.001 0.001"/>
    </geometry>
  </collision>
</link>

<link name="leg_fl_v61foot_fl1">
  <inertial>
    <origin rpy="0 0 0" xyz="0.006000000000000033 0.012499677502770146 -0.008293661771179406"/>
    <mass value="0.02"/>
    <inertia ixx="0.0000057" ixy="0" ixz="0" iyy="0.0000037" iyz="0" izz="0.0000031"/>
  </inertial>
  <visual>
    <origin rpy="0 0 0" xyz="0.155 -0.395885 0.375"/>
    <geometry>
      <mesh filename="meshes/leg_fl_v61foot_fl1.stl" scale="0.001 0.001 0.001"/>
    </geometry>
    <material name="silver"/>
    <material/>
  </visual>
  <collision>
    <origin rpy="0 0 0" xyz="0.155 -0.395885 0.375"/>
    <geometry>
      <mesh filename="meshes/leg_fl_v61foot_fl1.stl" scale="0.001 0.001 0.001"/>
    </geometry>
  </collision>
</link>

<link name="leg_fl_v61lowerleg_int_fl1">
  <inertial>
    <origin rpy="0 0 0" xyz="0.00250000000000003 0.012518038551013744 0.08933912489258466"/>
    <mass value="0.0448"/>
    <inertia ixx="0.000154" ixy="0" ixz="0" iyy="0.00014" iyz="0.000000066" izz="0.0000066"/>
  </inertial>
  <visual>
    <origin rpy="0 0 0" xyz="0.143 -0.395885 0.375"/>
    <geometry>
      <mesh filename="meshes/leg_fl_v61lowerleg_int_fl1.stl" scale="0.001 0.001 0.001"/>
    </geometry>
    <material name="silver"/>
    <material/>
  </visual>
  <collision>
    <origin rpy="0 0 0" xyz="0.143 -0.395885 0.375"/>
    <geometry>
      <mesh filename="meshes/leg_fl_v61lowerleg_int_fl1.stl" scale="0.001 0.001 0.001"/>
    </geometry>
  </collision>
</link>









<link name="leg_fr_v81motor_1_fr1">
  <inertial>
    <origin rpy="0 0 0" xyz="-6.022959908591474e-15 0.026228618678054205 0.027782105819294068"/>
    <mass value="0.71"/>
    <inertia ixx="0.00525" ixy="0" ixz="0" iyy="0.000807" iyz="0.0000114" izz="0.00051"/>
  </inertial>
  <visual>
    <origin rpy="0 0 0" xyz="-0.079 -0.305885 0.0345"/>
    <geometry>
      <mesh filename="meshes/leg_fr_v81motor_1_fr1.stl" scale="0.001 0.001 0.001"/>
    </geometry>
    <material name="silver"/>
    <material/>
  </visual>
  <collision>
    <origin rpy="0 0 0" xyz="-0.079 -0.305885 0.0345"/>
    <geometry>
      <mesh filename="meshes/leg_fr_v81motor_1_fr1.stl" scale="0.001 0.001 0.001"/>
    </geometry>
  </collision>
</link>

<link name="leg_fr_v81scap_x_y_fr1">
  <inertial>
    <origin rpy="0 0 0" xyz="-0.002167993084613448 0.011009286173284227 1.5629858518551032e-15"/>
    <mass value="0.0325"/>
    <inertia ixx="0.000014" ixy="-0.00000057" ixz="0" iyy="0.000015" iyz="" izz="0.0000041"/>
  </inertial>
  <visual>
    <origin rpy="0 0 0" xyz="-0.079 -0.354385 0.0075"/>
    <geometry>
      <mesh filename="meshes/leg_fr_v81scap_x_y_fr1.stl" scale="0.001 0.001 0.001"/>
    </geometry>
    <material name="silver"/>
    <material/>
  </visual>
  <collision>
    <origin rpy="0 0 0" xyz="-0.079 -0.354385 0.0075"/>
    <geometry>
      <mesh filename="meshes/leg_fr_v81scap_x_y_fr1.stl" scale="0.001 0.001 0.001"/>
    </geometry>
  </collision>
</link>

<link name="leg_fr_v81motor_2_fr1">
  <inertial>
    <origin rpy="0 0 0" xyz="0.014728950785939082 0.04199966789212067 0.0007821058192940501"/>
    <mass value="0.71"/>
    <inertia ixx="0.00087" ixy="0" ixz="0.0000115" iyy="0.00051" iyz="0" izz="0.00051"/>
  </inertial>
  <visual>
    <origin rpy="0 0 0" xyz="-0.091 -0.366385 0.0075"/>
    <geometry>
      <mesh filename="meshes/leg_fr_v81motor_2_fr1.stl" scale="0.001 0.001 0.001"/>
    </geometry>
    <material name="silver"/>
    <material/>
  </visual>
  <collision>
    <origin rpy="0 0 0" xyz="-0.091 -0.366385 0.0075"/>
    <geometry>
      <mesh filename="meshes/leg_fr_v81motor_2_fr1.stl" scale="0.001 0.001 0.001"/>
    </geometry>
  </collision>
</link>

<link name="leg_fr_v81upperleg_int_fr1">
  <inertial>
    <origin rpy="0 0 0" xyz="0.0024999999999988365 -3.321078855256232e-07 -0.10894505554394371"/>
    <mass value="0.056"/>
    <inertia ixx="0.00031" ixy="0" ixz="0" iyy="0.00029" iyz="0" izz="0.0000084"/>
  </inertial>
  <visual>
    <origin rpy="0 0 0" xyz="-0.128 -0.408385 0.0075"/>
    <geometry>
      <mesh filename="meshes/leg_fr_v81upperleg_int_fr1.stl" scale="0.001 0.001 0.001"/>
    </geometry>
    <material name="silver"/>
    <material/>
  </visual>
  <collision>
    <origin rpy="0 0 0" xyz="-0.128 -0.408385 0.0075"/>
    <geometry>
      <mesh filename="meshes/leg_fr_v81upperleg_int_fr1.stl" scale="0.001 0.001 0.001"/>
    </geometry>
  </collision>
</link>

<link name="leg_fr_v81link_motor_2_3_fr1">
  <inertial>
    <origin rpy="0 0 0" xyz="0.017914510831098962 -3.3210788058513074e-07 0.007534024575946585"/>
    <mass value="0.104"/>
    <inertia ixx="0.00017" ixy="0" ixz="-0.0000036" iyy="0.000083" iyz="0" izz="0.00011"/>
  </inertial>
  <visual>
    <origin rpy="0 0 0" xyz="-0.128 -0.408385 0.0075"/>
    <geometry>
      <mesh filename="meshes/leg_fr_v81link_motor_2_3_fr1.stl" scale="0.001 0.001 0.001"/>
    </geometry>
    <material name="silver"/>
    <material/>
  </visual>
  <collision>
    <origin rpy="0 0 0" xyz="-0.128 -0.408385 0.0075"/>
    <geometry>
      <mesh filename="meshes/leg_fr_v81link_motor_2_3_fr1.stl" scale="0.001 0.001 0.001"/>
    </geometry>
  </collision>
</link>

<link name="leg_fr_v81upperleg_ext_fr1">
  <inertial>
    <origin rpy="0 0 0" xyz="0.0024999999999987532 -3.322518460358026e-07 -0.08837314619383613"/>
    <mass value="0.067"/>
    <inertia ixx="0.00049" ixy="0.0" ixz="0" iyy="0.000462" iyz="0" izz="0.0000266"/>>
  </inertial>
  <visual>
    <origin rpy="0 0 0" xyz="-0.165 -0.408385 0.0075"/>
    <geometry>
      <mesh filename="meshes/leg_fr_v81upperleg_ext_fr1.stl" scale="0.001 0.001 0.001"/>
    </geometry>
    <material name="silver"/>
    <material/>
  </visual>
  <collision>
    <origin rpy="0 0 0" xyz="-0.165 -0.408385 0.0075"/>
    <geometry>
      <mesh filename="meshes/leg_fr_v81upperleg_ext_fr1.stl" scale="0.001 0.001 0.001"/>
    </geometry>
  </collision>
</link>

<link name="leg_fr_v81motor_3_fr1">
  <inertial>
    <origin rpy="0 0 0" xyz="0.02227104921405859 -3.321078905216268e-07 0.0007821058192940076"/>
    <mass value="0.71"/>
    <inertia ixx="0.00081" ixy="0" ixz="-0.000001152" iyy="0.000525" iyz="0" izz="0.00051"/>
  </inertial>
  <visual>
    <origin rpy="0 0 0" xyz="-0.168 -0.408385 0.0075"/>
    <geometry>
      <mesh filename="meshes/leg_fr_v81motor_3_fr1.stl" scale="0.001 0.001 0.001"/>
    </geometry>
    <material name="silver"/>
    <material/>
  </visual>
  <collision>
    <origin rpy="0 0 0" xyz="-0.168 -0.408385 0.0075"/>
    <geometry>
      <mesh filename="meshes/leg_fr_v81motor_3_fr1.stl" scale="0.001 0.001 0.001"/>
    </geometry>
  </collision>
</link>

<link name="leg_fr_v81lowerleg_int_fr1">
  <inertial>
    <origin rpy="0 0 0" xyz="0.0024999999999987532 -1.869315613289846e-05 -0.08216087510741729"/>
    <mass value="0.0448"/>
    <inertia ixx="0.000154" ixy="0" ixz="0" iyy="0.00014" iyz="-0.000000066" izz="0.0000066"/>
  </inertial>
  <visual>
    <origin rpy="0 0 0" xyz="-0.138 -0.408385 0.2035"/>
    <geometry>
      <mesh filename="meshes/leg_fr_v81lowerleg_int_fr1.stl" scale="0.001 0.001 0.001"/>
    </geometry>
    <material name="silver"/>
    <material/>
  </visual>
  <collision>
    <origin rpy="0 0 0" xyz="-0.138 -0.408385 0.2035"/>
    <geometry>
      <mesh filename="meshes/leg_fr_v81lowerleg_int_fr1.stl" scale="0.001 0.001 0.001"/>
    </geometry>
  </collision>
</link>

<link name="leg_fr_v81foot_fr1">
  <inertial>
    <origin rpy="0 0 0" xyz="0.005999999999998895 0.01249966789211987 -0.008293661771181182"/>
    <mass value="0.02"/>
    <inertia ixx="0.0000057" ixy="0" ixz="0" iyy="0.0000037" iyz="0" izz="0.0000031"/>
  </inertial>
  <visual>
    <origin rpy="0 0 0" xyz="-0.143 -0.395885 0.375"/>
    <geometry>
      <mesh filename="meshes/leg_fr_v81foot_fr1.stl" scale="0.001 0.001 0.001"/>
    </geometry>
    <material name="silver"/>
    <material/>
  </visual>
  <collision>
    <origin rpy="0 0 0" xyz="-0.143 -0.395885 0.375"/>
    <geometry>
      <mesh filename="meshes/leg_fr_v81foot_fr1.stl" scale="0.001 0.001 0.001"/>
    </geometry>
  </collision>
</link>

<link name="leg_fr_v81lowerleg_ext_fr1">
  <inertial>
    <origin rpy="0 0 0" xyz="0.002499999999998781 0.012481306843867057 0.08933912489258294"/>
    <mass value="0.0448"/>
    <inertia ixx="0.000154" ixy="0" ixz="0" iyy="0.00014" iyz="-0.000000066" izz="0.0000066"/>
  </inertial>
  <visual>
    <origin rpy="0 0 0" xyz="-0.155 -0.395885 0.375"/>
    <geometry>
      <mesh filename="meshes/leg_fr_v81lowerleg_ext_fr1.stl" scale="0.001 0.001 0.001"/>
    </geometry>
    <material name="silver"/>
    <material/>
  </visual>
  <collision>
    <origin rpy="0 0 0" xyz="-0.155 -0.395885 0.375"/>
    <geometry>
      <mesh filename="meshes/leg_fr_v81lowerleg_ext_fr1.stl" scale="0.001 0.001 0.001"/>
    </geometry>
  </collision>
</link>









<link name="leg_bl_v21motor_1_bl1">
  <inertial>
    <origin rpy="0 0 0" xyz="6.1201044232461754e-15 -0.026228618678054344 0.027782105819294082"/>
        <mass value="0.71"/>
    <inertia ixx="0.00525" ixy="0" ixz="0" iyy="0.000807" iyz="-0.0000114" izz="0.00051"/>
  </inertial>
  <visual>
    <origin rpy="0 0 0" xyz="0.079 -0.194115 0.0345"/>
    <geometry>
      <mesh filename="meshes/leg_bl_v21motor_1_bl1.stl" scale="0.001 0.001 0.001"/>
    </geometry>
    <material name="silver"/>
    <material/>
  </visual>
  <collision>
    <origin rpy="0 0 0" xyz="0.079 -0.194115 0.0345"/>
    <geometry>
      <mesh filename="meshes/leg_bl_v21motor_1_bl1.stl" scale="0.001 0.001 0.001"/>
    </geometry>
  </collision>
</link>

<link name="leg_bl_v21scap_x_y_bl1">
  <inertial>
    <origin rpy="0 0 0" xyz="0.002167993084613268 -0.011009286173284422 1.5716594692349872e-15"/>
    <mass value="0.0325"/>
    <inertia ixx="0.000014" ixy="-0.00000057" ixz="0" iyy="0.000015" iyz="" izz="0.0000041"/>
  </inertial>
  <visual>
    <origin rpy="0 0 0" xyz="0.079 -0.145615 0.0075"/>
    <geometry>
      <mesh filename="meshes/leg_bl_v21scap_x_y_bl1.stl" scale="0.001 0.001 0.001"/>
    </geometry>
    <material name="silver"/>
    <material/>
  </visual>
  <collision>
    <origin rpy="0 0 0" xyz="0.079 -0.145615 0.0075"/>
    <geometry>
      <mesh filename="meshes/leg_bl_v21scap_x_y_bl1.stl" scale="0.001 0.001 0.001"/>
    </geometry>
  </collision>
</link>

<link name="leg_bl_v21motor_2_bl1">
  <inertial>
    <origin rpy="0 0 0" xyz="-0.01472895078593918 -0.04199966789212073 0.0007821058192940588"/>
    <mass value="0.71"/>
    <inertia ixx="0.00087" ixy="0" ixz="-0.0000115" iyy="0.00051" iyz="0" izz="0.00051"/>
  </inertial>
  <visual>
    <origin rpy="0 0 0" xyz="0.091 -0.133615 0.0075"/>
    <geometry>
      <mesh filename="meshes/leg_bl_v21motor_2_bl1.stl" scale="0.001 0.001 0.001"/>
    </geometry>
    <material name="silver"/>
    <material/>
  </visual>
  <collision>
    <origin rpy="0 0 0" xyz="0.091 -0.133615 0.0075"/>
    <geometry>
      <mesh filename="meshes/leg_bl_v21motor_2_bl1.stl" scale="0.001 0.001 0.001"/>
    </geometry>
  </collision>
</link>

<link name="leg_bl_v21upperleg_int_bl1">
  <inertial>
    <origin rpy="0 0 0" xyz="-0.002499999999998892 3.321078855256232e-07 -0.10894505554394371"/>
    <mass value="0.056"/>
    <inertia ixx="0.00031" ixy="0" ixz="0" iyy="0.00029" iyz="0" izz="0.0000084"/>
  </inertial>
  <visual>
    <origin rpy="0 0 0" xyz="0.128 -0.091615 0.0075"/>
    <geometry>
      <mesh filename="meshes/leg_bl_v21upperleg_int_bl1.stl" scale="0.001 0.001 0.001"/>
    </geometry>
    <material name="silver"/>
    <material/>
  </visual>
  <collision>
    <origin rpy="0 0 0" xyz="0.128 -0.091615 0.0075"/>
    <geometry>
      <mesh filename="meshes/leg_bl_v21upperleg_int_bl1.stl" scale="0.001 0.001 0.001"/>
    </geometry>
  </collision>
</link>

<link name="leg_bl_v21link_motor_2_3_bl1">
  <inertial>
    <origin rpy="0 0 0" xyz="-0.017914510831099045 3.321078804324751e-07 0.007534024575946594"/>
    <mass value="0.104"/>
    <inertia ixx="0.00017" ixy="0" ixz="0.0000036" iyy="0.000083" iyz="0" izz="0.00011"/>
  </inertial>
  <visual>
    <origin rpy="0 0 0" xyz="0.128 -0.091615 0.0075"/>
    <geometry>
      <mesh filename="meshes/leg_bl_v21link_motor_2_3_bl1.stl" scale="0.001 0.001 0.001"/>
    </geometry>
    <material name="silver"/>
    <material/>
  </visual>
  <collision>
    <origin rpy="0 0 0" xyz="0.128 -0.091615 0.0075"/>
    <geometry>
      <mesh filename="meshes/leg_bl_v21link_motor_2_3_bl1.stl" scale="0.001 0.001 0.001"/>
    </geometry>
  </collision>
</link>

<link name="leg_bl_v21upperleg_ext_bl1">
  <inertial>
    <origin rpy="0 0 0" xyz="-0.002499999999998781 3.322518460496804e-07 -0.08837314619383613"/>
    <mass value="0.067"/>
    <inertia ixx="0.00049" ixy="0.0" ixz="0" iyy="0.000462" iyz="0" izz="0.0000266"/>
  </inertial>
  <visual>
    <origin rpy="0 0 0" xyz="0.165 -0.091615 0.0075"/>
    <geometry>
      <mesh filename="meshes/leg_bl_v21upperleg_ext_bl1.stl" scale="0.001 0.001 0.001"/>
    </geometry>
    <material name="silver"/>
    <material/>
  </visual>
  <collision>
    <origin rpy="0 0 0" xyz="0.165 -0.091615 0.0075"/>
    <geometry>
      <mesh filename="meshes/leg_bl_v21upperleg_ext_bl1.stl" scale="0.001 0.001 0.001"/>
    </geometry>
  </collision>
</link>

<link name="leg_bl_v21motor_3_bl1">
  <inertial>
    <origin rpy="0 0 0" xyz="-0.022271049214058897 3.321078904383601e-07 0.0007821058192940249"/>
    <mass value="0.71"/>
    <inertia ixx="0.00081" ixy="0" ixz="0.000001152" iyy="0.000525" iyz="0" izz="0.00051"/>
  </inertial>
  <visual>
    <origin rpy="0 0 0" xyz="0.168 -0.091615 0.0075"/>
    <geometry>
      <mesh filename="meshes/leg_bl_v21motor_3_bl1.stl" scale="0.001 0.001 0.001"/>
    </geometry>
    <material name="silver"/>
    <material/>
  </visual>
  <collision>
    <origin rpy="0 0 0" xyz="0.168 -0.091615 0.0075"/>
    <geometry>
      <mesh filename="meshes/leg_bl_v21motor_3_bl1.stl" scale="0.001 0.001 0.001"/>
    </geometry>
  </collision>
</link>

<link name="leg_bl_v21lowerleg_int_bl1">
  <inertial>
    <origin rpy="0 0 0" xyz="-0.0024999999999988365 1.8693156132856825e-05 -0.08216087510741724"/>
    <mass value="0.0448"/>
    <inertia ixx="0.000154" ixy="0" ixz="0" iyy="0.00014" iyz="0.000000066" izz="0.0000066"/>
  </inertial>
  <visual>
    <origin rpy="0 0 0" xyz="0.138 -0.091615 0.2035"/>
    <geometry>
      <mesh filename="meshes/leg_bl_v21lowerleg_int_bl1.stl" scale="0.001 0.001 0.001"/>
    </geometry>
    <material name="silver"/>
    <material/>
  </visual>
  <collision>
    <origin rpy="0 0 0" xyz="0.138 -0.091615 0.2035"/>
    <geometry>
      <mesh filename="meshes/leg_bl_v21lowerleg_int_bl1.stl" scale="0.001 0.001 0.001"/>
    </geometry>
  </collision>
</link>

<link name="leg_bl_v21foot_bl1">
  <inertial>
    <origin rpy="0 0 0" xyz="-0.005999999999998923 -0.012499667892119884 -0.008293661771181127"/>
    <mass value="0.02"/>
    <inertia ixx="0.0000057" ixy="0" ixz="0" iyy="0.0000037" iyz="0" izz="0.0000031"/>
  </inertial>
  <visual>
    <origin rpy="0 0 0" xyz="0.143 -0.104115 0.375"/>
    <geometry>
      <mesh filename="meshes/leg_bl_v21foot_bl1.stl" scale="0.001 0.001 0.001"/>
    </geometry>
    <material name="silver"/>
    <material/>
  </visual>
  <collision>
    <origin rpy="0 0 0" xyz="0.143 -0.104115 0.375"/>
    <geometry>
      <mesh filename="meshes/leg_bl_v21foot_bl1.stl" scale="0.001 0.001 0.001"/>
    </geometry>
  </collision>
</link>

<link name="leg_bl_v21lowerleg_ext_bl1">
  <inertial>
    <origin rpy="0 0 0" xyz="-0.0024999999999989475 -0.012481306843867099 0.08933912489258294"/>
    <mass value="0.0448"/>
    <inertia ixx="0.000154" ixy="0" ixz="0" iyy="0.00014" iyz="0.000000066" izz="0.0000066"/>
  </inertial>
  <visual>
    <origin rpy="0 0 0" xyz="0.155 -0.104115 0.375"/>
    <geometry>
      <mesh filename="meshes/leg_bl_v21lowerleg_ext_bl1.stl" scale="0.001 0.001 0.001"/>
    </geometry>
    <material name="silver"/>
    <material/>
  </visual>
  <collision>
    <origin rpy="0 0 0" xyz="0.155 -0.104115 0.375"/>
    <geometry>
      <mesh filename="meshes/leg_bl_v21lowerleg_ext_bl1.stl" scale="0.001 0.001 0.001"/>
    </geometry>
  </collision>
</link>

<link name="leg_br_v21motor_1_br1">
  <inertial>
    <origin rpy="0 0 0" xyz="5.856426454897701e-15 -0.026228618678054372 0.027782105819294068"/>
    <mass value="0.71"/>
    <inertia ixx="0.00525" ixy="0" ixz="0" iyy="0.000807" iyz="-0.0000114" izz="0.00051"/>
  </inertial>
  <visual>
    <origin rpy="0 0 0" xyz="-0.079 -0.194115 0.0345"/>
    <geometry>
      <mesh filename="meshes/leg_br_v21motor_1_br1.stl" scale="0.001 0.001 0.001"/>
    </geometry>
    <material name="silver"/>
    <material/>
  </visual>
  <collision>
    <origin rpy="0 0 0" xyz="-0.079 -0.194115 0.0345"/>
    <geometry>
      <mesh filename="meshes/leg_br_v21motor_1_br1.stl" scale="0.001 0.001 0.001"/>
    </geometry>
  </collision>
</link>

<link name="leg_br_v21scap_x_y_br1">
  <inertial>
    <origin rpy="0 0 0" xyz="-0.0021679930846135315 -0.011009286173284505 -1.5785983631388945e-15"/>
	<mass value="0.0325"/>
    <inertia ixx="0.000014" ixy="0.00000057" ixz="0" iyy="0.000015" iyz="" izz="0.0000041"/>
  </inertial>
  <visual>
    <origin rpy="0 0 0" xyz="-0.079 -0.145615 0.0075"/>
    <geometry>
      <mesh filename="meshes/leg_br_v21scap_x_y_br1.stl" scale="0.001 0.001 0.001"/>
    </geometry>
    <material name="silver"/>
    <material/>
  </visual>
  <collision>
    <origin rpy="0 0 0" xyz="-0.079 -0.145615 0.0075"/>
    <geometry>
      <mesh filename="meshes/leg_br_v21scap_x_y_br1.stl" scale="0.001 0.001 0.001"/>
    </geometry>
  </collision>
</link>

<link name="leg_br_v21motor_2_br1">
  <inertial>
    <origin rpy="0 0 0" xyz="0.014728950785940179 -0.04199966789210828 0.0007821058192939764"/>
    <mass value="0.71"/>
    <inertia ixx="0.00087" ixy="0" ixz="0.0000115" iyy="0.00051" iyz="0" izz="0.00051"/>
  </inertial>
  <visual>
    <origin rpy="0 0 0" xyz="-0.091 -0.133615 0.0075"/>
    <geometry>
      <mesh filename="meshes/leg_br_v21motor_2_br1.stl" scale="0.001 0.001 0.001"/>
    </geometry>
    <material name="silver"/>
    <material/>
  </visual>
  <collision>
    <origin rpy="0 0 0" xyz="-0.091 -0.133615 0.0075"/>
    <geometry>
      <mesh filename="meshes/leg_br_v21motor_2_br1.stl" scale="0.001 0.001 0.001"/>
    </geometry>
  </collision>
</link>

<link name="leg_br_v21upperleg_int_br1">
  <inertial>
    <origin rpy="0 0 0" xyz="0.0025000000000001132 3.321078863305349e-07 -0.10894505554394376"/>
    <mass value="0.056"/>
    <inertia ixx="0.00031" ixy="0" ixz="0" iyy="0.00029" iyz="0" izz="0.0000084"/>
  </inertial>
  <visual>
    <origin rpy="0 0 0" xyz="-0.128 -0.091615 0.0075"/>
    <geometry>
      <mesh filename="meshes/leg_br_v21upperleg_int_br1.stl" scale="0.001 0.001 0.001"/>
    </geometry>
    <material name="silver"/>
    <material/>
  </visual>
  <collision>
    <origin rpy="0 0 0" xyz="-0.128 -0.091615 0.0075"/>
    <geometry>
      <mesh filename="meshes/leg_br_v21upperleg_int_br1.stl" scale="0.001 0.001 0.001"/>
    </geometry>
  </collision>
</link>

<link name="leg_br_v21link_motor_2_3_br1">
  <inertial>
    <origin rpy="0 0 0" xyz="0.01791451083109999 3.321078897583485e-07 0.007534024575946553"/>
    <mass value="0.104"/>
    <inertia ixx="0.00017" ixy="0" ixz="-0.0000036" iyy="0.000083" iyz="0" izz="0.00011"/>
  </inertial>
  <visual>
    <origin rpy="0 0 0" xyz="-0.128 -0.091615 0.0075"/>
    <geometry>
      <mesh filename="meshes/leg_br_v21link_motor_2_3_br1.stl" scale="0.001 0.001 0.001"/>
    </geometry>
    <material name="silver"/>
    <material/>
  </visual>
  <collision>
    <origin rpy="0 0 0" xyz="-0.128 -0.091615 0.0075"/>
    <geometry>
      <mesh filename="meshes/leg_br_v21link_motor_2_3_br1.stl" scale="0.001 0.001 0.001"/>
    </geometry>
  </collision>
</link>

<link name="leg_br_v21upperleg_ext_br1">
  <inertial>
    <origin rpy="0 0 0" xyz="0.002500000000000141 3.322518467435698e-07 -0.08837314619383613"/>
    <mass value="0.067"/>
    <inertia ixx="0.00049" ixy="0.0" ixz="0" iyy="0.000462" iyz="0" izz="0.0000266"/>
  </inertial>
  <visual>
    <origin rpy="0 0 0" xyz="-0.165 -0.091615 0.0075"/>
    <geometry>
      <mesh filename="meshes/leg_br_v21upperleg_ext_br1.stl" scale="0.001 0.001 0.001"/>
    </geometry>
    <material name="silver"/>
    <material/>
  </visual>
  <collision>
    <origin rpy="0 0 0" xyz="-0.165 -0.091615 0.0075"/>
    <geometry>
      <mesh filename="meshes/leg_br_v21upperleg_ext_br1.stl" scale="0.001 0.001 0.001"/>
    </geometry>
  </collision>
</link>

<link name="leg_br_v21motor_3_br1">
  <inertial>
    <origin rpy="0 0 0" xyz="0.02227104921405959 3.321078791418408e-07 0.0007821058192940362"/>
    <mass value="0.71"/>
    <inertia ixx="0.00081" ixy="0" ixz="-0.000001152" iyy="0.000525" iyz="0" izz="0.00051"/>
  </inertial>
  <visual>
    <origin rpy="0 0 0" xyz="-0.168 -0.091615 0.0075"/>
    <geometry>
      <mesh filename="meshes/leg_br_v21motor_3_br1.stl" scale="0.001 0.001 0.001"/>
    </geometry>
    <material name="silver"/>
    <material/>
  </visual>
  <collision>
    <origin rpy="0 0 0" xyz="-0.168 -0.091615 0.0075"/>
    <geometry>
      <mesh filename="meshes/leg_br_v21motor_3_br1.stl" scale="0.001 0.001 0.001"/>
    </geometry>
  </collision>
</link>

<link name="leg_br_v21lowerleg_ext_br1">
  <inertial>
    <origin rpy="0 0 0" xyz="-0.00250000000000003 -1.8038551014093462e-05 -0.08216087510741535"/>
    <mass value="0.0448"/>
    <inertia ixx="0.000154" ixy="0" ixz="0" iyy="0.00014" iyz="-0.000000066" izz="0.0000066"/>
  </inertial>
  <visual>
    <origin rpy="0 0 0" xyz="-0.16 -0.091615 0.2035"/>
    <geometry>
      <mesh filename="meshes/leg_br_v21lowerleg_ext_br1.stl" scale="0.001 0.001 0.001"/>
    </geometry>
    <material name="silver"/>
    <material/>
  </visual>
  <collision>
    <origin rpy="0 0 0" xyz="-0.16 -0.091615 0.2035"/>
    <geometry>
      <mesh filename="meshes/leg_br_v21lowerleg_ext_br1.stl" scale="0.001 0.001 0.001"/>
    </geometry>
  </collision>
</link>

<link name="leg_br_v21foot_br1">
  <inertial>
    <origin rpy="0 0 0" xyz="-0.006000000000000144 -0.012499677502770437 -0.00829366177117935"/>
    <mass value="0.02"/>
    <inertia ixx="0.0000057" ixy="0" ixz="0" iyy="0.0000037" iyz="0" izz="0.0000031"/>
  </inertial>
  <visual>
    <origin rpy="0 0 0" xyz="-0.155 -0.104115 0.375"/>
    <geometry>
      <mesh filename="meshes/leg_br_v21foot_br1.stl" scale="0.001 0.001 0.001"/>
    </geometry>
    <material name="silver"/>
    <material/>
  </visual>
  <collision>
    <origin rpy="0 0 0" xyz="-0.155 -0.104115 0.375"/>
    <geometry>
      <mesh filename="meshes/leg_br_v21foot_br1.stl" scale="0.001 0.001 0.001"/>
    </geometry>
  </collision>
</link>

<link name="leg_br_v21lowerleg_int_br1">
  <inertial>
    <origin rpy="0 0 0" xyz="-0.0025000000000001132 -0.01251803855101391 0.08933912489258466"/>
    <mass value="0.0448"/>
    <inertia ixx="0.000154" ixy="0" ixz="0" iyy="0.00014" iyz="-0.000000066" izz="0.0000066"/>
  </inertial>
  <visual>
    <origin rpy="0 0 0" xyz="-0.143 -0.104115 0.375"/>
    <geometry>
      <mesh filename="meshes/leg_br_v21lowerleg_int_br1.stl" scale="0.001 0.001 0.001"/>
    </geometry>
    <material name="silver"/>
    <material/>
  </visual>
  <collision>
    <origin rpy="0 0 0" xyz="-0.143 -0.104115 0.375"/>
    <geometry>
      <mesh filename="meshes/leg_br_v21lowerleg_int_br1.stl" scale="0.001 0.001 0.001"/>
    </geometry>
  </collision>
</link>











<joint name="Rigid1" type="fixed">
  <origin rpy="0 0 0" xyz="-0.079 0.298 0.0"/>
  <parent link="base_link"/>
  <child link="leg_fl_v61body_leg_fl1"/>
</joint>

<joint name="Rigid2" type="fixed">
  <origin rpy="0 0 0" xyz="0.079 0.298 0.0"/>
  <parent link="base_link"/>
  <child link="leg_fr_v81body_leg_fr1"/>
</joint>

<joint name="Rigid3" type="fixed">
  <origin rpy="0 0 0" xyz="-0.079 0.202 0.0"/>
  <parent link="base_link"/>
  <child link="leg_bl_v21body_leg_bl1"/>
</joint>

<joint name="Rigid4" type="fixed">
  <origin rpy="0 0 0" xyz="0.079 0.202 0.0"/>
  <parent link="base_link"/>
  <child link="leg_br_v21body_leg_br1"/>
</joint>

<joint name="leg_fl_v61_Rigid1_fl" type="fixed">
  <origin rpy="0 0 0" xyz="0.0 0.007885 -0.0345"/>
  <parent link="leg_fl_v61body_leg_fl1"/>
  <child link="leg_fl_v61motor_1_fl1"/>
</joint>

<joint name="leg_fl_v61_sh_x_fl" type="continuous">
  <origin rpy="0 0 0" xyz="0.0 0.0485 0.027"/>
  <parent link="leg_fl_v61motor_1_fl1"/>
  <child link="leg_fl_v61scap_x_y_fl1"/>
  <axis xyz="-0.0 1.0 0.0"/>
</joint>
<transmission name="leg_fl_v61_sh_x_fl_tran">
  <type>transmission_interface/SimpleTransmission</type>
  <joint name="leg_fl_v61_sh_x_fl">
    <hardwareInterface>PositionJointInterface</hardwareInterface>
  </joint>
  <actuator name="leg_fl_v61_sh_x_fl_actr">
    <hardwareInterface>PositionJointInterface</hardwareInterface>
    <mechanicalReduction>1</mechanicalReduction>
  </actuator>
</transmission>

<joint name="leg_fl_v61_Rigid3_fl" type="fixed">
  <origin rpy="0 0 0" xyz="-0.012 0.012 0.0"/>
  <parent link="leg_fl_v61scap_x_y_fl1"/>
  <child link="leg_fl_v61motor_2_fl1"/>
</joint>

<joint name="leg_fl_v61_sh_y_fl" type="continuous">
  <origin rpy="0 0 0" xyz="-0.037 0.042 0.0"/>
  <parent link="leg_fl_v61motor_2_fl1"/>
  <child link="leg_fl_v61upperleg_int_fl1"/>
  <axis xyz="-1.0 0.0 0.0"/>
</joint>
<transmission name="leg_fl_v61_sh_y_fl_tran">
  <type>transmission_interface/SimpleTransmission</type>
  <joint name="leg_fl_v61_sh_y_fl">
    <hardwareInterface>PositionJointInterface</hardwareInterface>
  </joint>
  <actuator name="leg_fl_v61_sh_y_fl_actr">
    <hardwareInterface>PositionJointInterface</hardwareInterface>
    <mechanicalReduction>1</mechanicalReduction>
  </actuator>
</transmission>

<joint name="leg_fl_v61_Rigid5_fl" type="fixed">
  <origin rpy="0 0 0" xyz="0.0 0.0 0.0"/>
  <parent link="leg_fl_v61upperleg_int_fl1"/>
  <child link="leg_fl_v61link_motor_2_3_fl1"/>
</joint>

<joint name="leg_fl_v61_Rigid6_fl" type="fixed">
  <origin rpy="0 0 0" xyz="-0.037 0.0 0.0"/>
  <parent link="leg_fl_v61link_motor_2_3_fl1"/>
  <child link="leg_fl_v61upperleg_ext_fl1"/>
</joint>

<joint name="leg_fl_v61_Rigid7_fl" type="fixed">
  <origin rpy="0 0 0" xyz="-0.003 0.0 0.0"/>
  <parent link="leg_fl_v61upperleg_ext_fl1"/>
  <child link="leg_fl_v61motor_3_fl1"/>
</joint>

<joint name="leg_fl_v61_el_fl" type="continuous">
  <origin rpy="0 0 0" xyz="0.005 0.0 -0.196"/>
  <parent link="leg_fl_v61upperleg_ext_fl1"/>
  <child link="leg_fl_v61lowerleg_ext_fl1"/>
  <axis xyz="1.0 0.0 -0.0"/>
</joint>
<transmission name="leg_fl_v61_el_fl_tran">
  <type>transmission_interface/SimpleTransmission</type>
  <joint name="leg_fl_v61_el_fl">
    <hardwareInterface>PositionJointInterface</hardwareInterface>
  </joint>
  <actuator name="leg_fl_v61_el_fl_actr">
    <hardwareInterface>PositionJointInterface</hardwareInterface>
    <mechanicalReduction>1</mechanicalReduction>
  </actuator>
</transmission>

<joint name="leg_fl_v61_Rigid9_fl" type="fixed">
  <origin rpy="0 0 0" xyz="0.005 -0.0125 -0.1715"/>
  <parent link="leg_fl_v61lowerleg_ext_fl1"/>
  <child link="leg_fl_v61foot_fl1"/>
</joint>

<joint name="leg_fl_v61_Rigid10_fl" type="fixed">
  <origin rpy="0 0 0" xyz="0.012 0.0 0.0"/>
  <parent link="leg_fl_v61foot_fl1"/>
  <child link="leg_fl_v61lowerleg_int_fl1"/>
</joint>

<joint name="leg_fr_v81_Rigid1_fr" type="fixed">
  <origin rpy="0 0 0" xyz="0.0 0.007885 -0.0345"/>
  <parent link="leg_fr_v81body_leg_fr1"/>
  <child link="leg_fr_v81motor_1_fr1"/>
</joint>

<joint name="leg_fr_v81_scap_x_fr" type="continuous">
  <origin rpy="0 0 0" xyz="0.0 0.0485 0.027"/>
  <parent link="leg_fr_v81motor_1_fr1"/>
  <child link="leg_fr_v81scap_x_y_fr1"/>
  <axis xyz="-0.0 1.0 0.0"/>
</joint>
<transmission name="leg_fr_v81_scap_x_fr_tran">
  <type>transmission_interface/SimpleTransmission</type>
  <joint name="leg_fr_v81_scap_x_fr">
    <hardwareInterface>PositionJointInterface</hardwareInterface>
  </joint>
  <actuator name="leg_fr_v81_scap_x_fr_actr">
    <hardwareInterface>PositionJointInterface</hardwareInterface>
    <mechanicalReduction>1</mechanicalReduction>
  </actuator>
</transmission>

<joint name="leg_fr_v81_Rigid3_fr" type="fixed">
  <origin rpy="0 0 0" xyz="0.012 0.012 0.0"/>
  <parent link="leg_fr_v81scap_x_y_fr1"/>
  <child link="leg_fr_v81motor_2_fr1"/>
</joint>

<joint name="leg_fr_v81_scap_y_fr" type="continuous">
  <origin rpy="0 0 0" xyz="0.037 0.042 0.0"/>
  <parent link="leg_fr_v81motor_2_fr1"/>
  <child link="leg_fr_v81upperleg_int_fr1"/>
  <axis xyz="1.0 0.0 -0.0"/>
</joint>
<transmission name="leg_fr_v81_scap_y_fr_tran">
  <type>transmission_interface/SimpleTransmission</type>
  <joint name="leg_fr_v81_scap_y_fr">
    <hardwareInterface>PositionJointInterface</hardwareInterface>
  </joint>
  <actuator name="leg_fr_v81_scap_y_fr_actr">
    <hardwareInterface>PositionJointInterface</hardwareInterface>
    <mechanicalReduction>1</mechanicalReduction>
  </actuator>
</transmission>

<joint name="leg_fr_v81_Rigid5_fr" type="fixed">
  <origin rpy="0 0 0" xyz="0.0 0.0 0.0"/>
  <parent link="leg_fr_v81upperleg_int_fr1"/>
  <child link="leg_fr_v81link_motor_2_3_fr1"/>
</joint>

<joint name="leg_fr_v81_Rigid6_fr" type="fixed">
  <origin rpy="0 0 0" xyz="0.037 0.0 0.0"/>
  <parent link="leg_fr_v81link_motor_2_3_fr1"/>
  <child link="leg_fr_v81upperleg_ext_fr1"/>
</joint>

<joint name="leg_fr_v81_Rigid7_fr" type="fixed">
  <origin rpy="0 0 0" xyz="0.003 0.0 0.0"/>
  <parent link="leg_fr_v81upperleg_ext_fr1"/>
  <child link="leg_fr_v81motor_3_fr1"/>
</joint>

<joint name="leg_fr_v81_el_fr" type="continuous">
  <origin rpy="0 0 0" xyz="0.01 0.0 -0.196"/>
  <parent link="leg_fr_v81upperleg_int_fr1"/>
  <child link="leg_fr_v81lowerleg_int_fr1"/>
  <axis xyz="1.0 0.0 -0.0"/>
</joint>
<transmission name="leg_fr_v81_el_fr_tran">
  <type>transmission_interface/SimpleTransmission</type>
  <joint name="leg_fr_v81_el_fr">
    <hardwareInterface>PositionJointInterface</hardwareInterface>
  </joint>
  <actuator name="leg_fr_v81_el_fr_actr">
    <hardwareInterface>PositionJointInterface</hardwareInterface>
    <mechanicalReduction>1</mechanicalReduction>
  </actuator>
</transmission>

<joint name="leg_fr_v81_Rigid9_fr" type="fixed">
  <origin rpy="0 0 0" xyz="0.005 -0.0125 -0.1715"/>
  <parent link="leg_fr_v81lowerleg_int_fr1"/>
  <child link="leg_fr_v81foot_fr1"/>
</joint>

<joint name="leg_fr_v81_Rigid10_fr" type="fixed">
  <origin rpy="0 0 0" xyz="0.012 0.0 0.0"/>
  <parent link="leg_fr_v81foot_fr1"/>
  <child link="leg_fr_v81lowerleg_ext_fr1"/>
</joint>

<joint name="leg_bl_v21_Rigid1_bl" type="fixed">
  <origin rpy="0 0 0" xyz="0.0 -0.007885 -0.0345"/>
  <parent link="leg_bl_v21body_leg_bl1"/>
  <child link="leg_bl_v21motor_1_bl1"/>
</joint>

<joint name="leg_bl_v21_scap_x_bl" type="continuous">
  <origin rpy="0 0 0" xyz="0.0 -0.0485 0.027"/>
  <parent link="leg_bl_v21motor_1_bl1"/>
  <child link="leg_bl_v21scap_x_y_bl1"/>
  <axis xyz="-0.0 -1.0 0.0"/>
</joint>
<transmission name="leg_bl_v21_scap_x_bl_tran">
  <type>transmission_interface/SimpleTransmission</type>
  <joint name="leg_bl_v21_scap_x_bl">
    <hardwareInterface>PositionJointInterface</hardwareInterface>
  </joint>
  <actuator name="leg_bl_v21_scap_x_bl_actr">
    <hardwareInterface>PositionJointInterface</hardwareInterface>
    <mechanicalReduction>1</mechanicalReduction>
  </actuator>
</transmission>

<joint name="leg_bl_v21_Rigid3_bl" type="fixed">
  <origin rpy="0 0 0" xyz="-0.012 -0.012 0.0"/>
  <parent link="leg_bl_v21scap_x_y_bl1"/>
  <child link="leg_bl_v21motor_2_bl1"/>
</joint>

<joint name="leg_bl_v21_scap_y_bl" type="continuous">
  <origin rpy="0 0 0" xyz="-0.037 -0.042 0.0"/>
  <parent link="leg_bl_v21motor_2_bl1"/>
  <child link="leg_bl_v21upperleg_int_bl1"/>
  <axis xyz="-1.0 -0.0 -0.0"/>
</joint>
<transmission name="leg_bl_v21_scap_y_bl_tran">
  <type>transmission_interface/SimpleTransmission</type>
  <joint name="leg_bl_v21_scap_y_bl">
    <hardwareInterface>PositionJointInterface</hardwareInterface>
  </joint>
  <actuator name="leg_bl_v21_scap_y_bl_actr">
    <hardwareInterface>PositionJointInterface</hardwareInterface>
    <mechanicalReduction>1</mechanicalReduction>
  </actuator>
</transmission>

<joint name="leg_bl_v21_Rigid5_bl" type="fixed">
  <origin rpy="0 0 0" xyz="0.0 0.0 0.0"/>
  <parent link="leg_bl_v21upperleg_int_bl1"/>
  <child link="leg_bl_v21link_motor_2_3_bl1"/>
</joint>

<joint name="leg_bl_v21_Rigid6_bl" type="fixed">
  <origin rpy="0 0 0" xyz="-0.037 0.0 0.0"/>
  <parent link="leg_bl_v21link_motor_2_3_bl1"/>
  <child link="leg_bl_v21upperleg_ext_bl1"/>
</joint>

<joint name="leg_bl_v21_Rigid7_bl" type="fixed">
  <origin rpy="0 0 0" xyz="-0.003 0.0 0.0"/>
  <parent link="leg_bl_v21upperleg_ext_bl1"/>
  <child link="leg_bl_v21motor_3_bl1"/>
</joint>

<joint name="leg_bl_v21_el_bl" type="continuous">
  <origin rpy="0 0 0" xyz="-0.01 0.0 -0.196"/>
  <parent link="leg_bl_v21upperleg_int_bl1"/>
  <child link="leg_bl_v21lowerleg_int_bl1"/>
  <axis xyz="-1.0 -0.0 -0.0"/>
</joint>
<transmission name="leg_bl_v21_el_bl_tran">
  <type>transmission_interface/SimpleTransmission</type>
  <joint name="leg_bl_v21_el_bl">
    <hardwareInterface>PositionJointInterface</hardwareInterface>
  </joint>
  <actuator name="leg_bl_v21_el_bl_actr">
    <hardwareInterface>PositionJointInterface</hardwareInterface>
    <mechanicalReduction>1</mechanicalReduction>
  </actuator>
</transmission>

<joint name="leg_bl_v21_Rigid9_bl" type="fixed">
  <origin rpy="0 0 0" xyz="-0.005 0.0125 -0.1715"/>
  <parent link="leg_bl_v21lowerleg_int_bl1"/>
  <child link="leg_bl_v21foot_bl1"/>
</joint>

<joint name="leg_bl_v21_Rigid10_bl" type="fixed">
  <origin rpy="0 0 0" xyz="-0.012 0.0 0.0"/>
  <parent link="leg_bl_v21foot_bl1"/>
  <child link="leg_bl_v21lowerleg_ext_bl1"/>
</joint>

<joint name="leg_br_v21_Rigid1_br" type="fixed">
  <origin rpy="0 0 0" xyz="0.0 -0.007885 -0.0345"/>
  <parent link="leg_br_v21body_leg_br1"/>
  <child link="leg_br_v21motor_1_br1"/>
</joint>

<joint name="leg_br_v21_sh_x_br" type="continuous">
  <origin rpy="0 0 0" xyz="0.0 -0.0485 0.027"/>
  <parent link="leg_br_v21motor_1_br1"/>
  <child link="leg_br_v21scap_x_y_br1"/>
  <axis xyz="-0.0 -1.0 0.0"/>
</joint>
<transmission name="leg_br_v21_sh_x_br_tran">
  <type>transmission_interface/SimpleTransmission</type>
  <joint name="leg_br_v21_sh_x_br">
    <hardwareInterface>PositionJointInterface</hardwareInterface>
  </joint>
  <actuator name="leg_br_v21_sh_x_br_actr">
    <hardwareInterface>PositionJointInterface</hardwareInterface>
    <mechanicalReduction>1</mechanicalReduction>
  </actuator>
</transmission>

<joint name="leg_br_v21_Rigid3_br" type="fixed">
  <origin rpy="0 0 0" xyz="0.012 -0.012 0.0"/>
  <parent link="leg_br_v21scap_x_y_br1"/>
  <child link="leg_br_v21motor_2_br1"/>
</joint>

<joint name="leg_br_v21_sh_y_br" type="continuous">
  <origin rpy="0 0 0" xyz="0.037 -0.042 0.0"/>
  <parent link="leg_br_v21motor_2_br1"/>
  <child link="leg_br_v21upperleg_int_br1"/>
  <axis xyz="1.0 -0.0 0.0"/>
</joint>
<transmission name="leg_br_v21_sh_y_br_tran">
  <type>transmission_interface/SimpleTransmission</type>
  <joint name="leg_br_v21_sh_y_br">
    <hardwareInterface>PositionJointInterface</hardwareInterface>
  </joint>
  <actuator name="leg_br_v21_sh_y_br_actr">
    <hardwareInterface>PositionJointInterface</hardwareInterface>
    <mechanicalReduction>1</mechanicalReduction>
  </actuator>
</transmission>

<joint name="leg_br_v21_Rigid5_br" type="fixed">
  <origin rpy="0 0 0" xyz="0.0 0.0 0.0"/>
  <parent link="leg_br_v21upperleg_int_br1"/>
  <child link="leg_br_v21link_motor_2_3_br1"/>
</joint>

<joint name="leg_br_v21_Rigid6_br" type="fixed">
  <origin rpy="0 0 0" xyz="0.037 0.0 0.0"/>
  <parent link="leg_br_v21link_motor_2_3_br1"/>
  <child link="leg_br_v21upperleg_ext_br1"/>
</joint>

<joint name="leg_br_v21_Rigid7_br" type="fixed">
  <origin rpy="0 0 0" xyz="0.003 0.0 0.0"/>
  <parent link="leg_br_v21upperleg_ext_br1"/>
  <child link="leg_br_v21motor_3_br1"/>
</joint>

<joint name="leg_br_v21_el_br" type="continuous">
  <origin rpy="0 0 0" xyz="-0.005 0.0 -0.196"/>
  <parent link="leg_br_v21upperleg_ext_br1"/>
  <child link="leg_br_v21lowerleg_ext_br1"/>
  <axis xyz="-1.0 0.0 -0.0"/>
</joint>
<transmission name="leg_br_v21_el_br_tran">
  <type>transmission_interface/SimpleTransmission</type>
  <joint name="leg_br_v21_el_br">
    <hardwareInterface>PositionJointInterface</hardwareInterface>
  </joint>
  <actuator name="leg_br_v21_el_br_actr">
    <hardwareInterface>PositionJointInterface</hardwareInterface>
    <mechanicalReduction>1</mechanicalReduction>
  </actuator>
</transmission>

<joint name="leg_br_v21_Rigid9_br" type="fixed">
  <origin rpy="0 0 0" xyz="-0.005 0.0125 -0.1715"/>
  <parent link="leg_br_v21lowerleg_ext_br1"/>
  <child link="leg_br_v21foot_br1"/>
</joint>

<joint name="leg_br_v21_Rigid10_br" type="fixed">
  <origin rpy="0 0 0" xyz="-0.012 0.0 0.0"/>
  <parent link="leg_br_v21foot_br1"/>
  <child link="leg_br_v21lowerleg_int_br1"/>
</joint>

</robot>
