<?xml version="1.0" ?>
<robot name="IdefX">
	<material name="black">
		<color rgba="0.0 0.0 0.0 1.0"/>
	</material>
	<material name="blue">
		<color rgba="0.0 0.0 0.8 1.0"/>
	</material>
	<material name="green">
		<color rgba="0.0 0.8 0.0 1.0"/>
	</material>
	<material name="grey">
		<color rgba="0.2 0.2 0.2 1.0"/>
	</material>
	<material name="silver">
		<color rgba="0.913725490196 0.913725490196 0.847058823529 1.0"/>
	</material>
	<material name="orange">
		<color rgba="1.0 0.423529411765 0.0392156862745 1.0"/>
	</material>
	<material name="brown">
		<color rgba="0.870588235294 0.811764705882 0.764705882353 1.0"/>
	</material>
	<material name="red">
		<color rgba="0.8 0.0 0.0 1.0"/>
	</material>
	<material name="white">
		<color rgba="1.0 1.0 1.0 1.0"/>
	</material>
	<link name="trunk">
		<visual>
			<origin rpy="0 0 0" xyz="0 0 0"/>
			<geometry>
				<box size="0.5 0.2 0.2"/>
			</geometry>
			<material name="grey"/>
		</visual>
		<collision>
			<origin rpy="0 0 0" xyz="0 0 0"/>
			<geometry>
				<box size="0.5 0.2 0.2"/>
			</geometry>
		</collision>
		<inertial>
			<origin rpy="0 0 0" xyz="0 0 0"/>
			<mass value="13"/>
			<inertia ixx="0.08666666666666668" ixy="0" ixz="0" iyy="0.3141666666666667" iyz="0" izz="0.3141666666666667"/>
		</inertial>
	</link>
	<joint name="FL_clavicle_joint" type="revolute">
		<origin rpy="0 0 0" xyz="0.25 0.15 0"/>
		<parent link="trunk"/>
		<child link="FL_clavicle"/>
		<axis xyz="1 0 0"/>
		<dynamics damping="0" friction="0"/>
		<limit effort="20"/>
	</joint>
	<link name="FL_clavicle">
		<visual>
			<origin rpy="0 0 0" xyz="0 0 0"/>
			<geometry>
				<box size="0.1 0.04 0.1"/>
			</geometry>
			<material name="blue"/>
		</visual>
		<collision>
			<origin rpy="0 0 0" xyz="0 0 0"/>
			<geometry>
				<box size="0.1 0.04 0.1"/>
			</geometry>
		</collision>
		<inertial>
			<origin rpy="0 0 0" xyz="0 0 0"/>
			<mass value="0.6"/>
			<inertia ixx="0.0005800000000000001" ixy="0" ixz="0" iyy="0.001" iyz="0" izz="0.0005800000000000001"/>
		</inertial>
	</link>
	<joint name="FL_arm_joint" type="revolute">
		<origin rpy="0 0 0" xyz="0 0.05 0"/>
		<parent link="FL_clavicle"/>
		<child link="FL_arm"/>
		<axis xyz="0 1 0"/>
		<dynamics damping="0" friction="0"/>
		<limit effort="20"/>
	</joint>
	<link name="FL_arm">
		<visual>
			<origin rpy="0 0 0" xyz="0 0 -0.115"/>
			<geometry>
				<box size="0.04 0.02 0.23"/>
			</geometry>
			<material name="grey"/>
		</visual>
		<collision>
			<origin rpy="0 0 0" xyz="0 0 -0.115"/>
			<geometry>
				<box size="0.04 0.02 0.23"/>
			</geometry>
		</collision>
		<inertial>
			<origin rpy="0 0 0" xyz="0 0 -0.115"/>
			<mass value="0.6"/>
			<inertia ixx="0.002665" ixy="0" ixz="0" iyy="0.0027249999999999996" iyz="0" izz="9.999999999999999e-05"/>
		</inertial>
	</link>
	<joint name="FL_forearm_joint" type="revolute">
		<origin rpy="0 0 0" xyz="0 0.03 -0.2"/>
		<parent link="FL_arm"/>
		<child link="FL_forearm"/>
		<axis xyz="0 1 0"/>
		<dynamics damping="0" friction="0"/>
		<limit effort="20"/>
	</joint>
	<link name="FL_forearm">
		<visual>
			<origin rpy="0 0 0" xyz="0 0 -0.1"/>
			<geometry>
				<box size="0.04 0.02 0.25"/>
			</geometry>
			<material name="grey"/>
		</visual>
		<collision>
			<origin rpy="0 0 0" xyz="0 0 -0.1"/>
			<geometry>
				<box size="0.04 0.02 0.25"/>
			</geometry>
		</collision>
		<inertial>
			<origin rpy="0 0 0" xyz="0 0 -0.1"/>
			<mass value="0.6"/>
			<inertia ixx="0.003145" ixy="0" ixz="0" iyy="0.003205" iyz="0" izz="9.999999999999999e-05"/>
		</inertial>
	</link>
	<joint name="FL_foot_joint" type="fixed">
		<origin rpy="0 0 0" xyz="0 0.01 -0.25"/>
		<parent link="FL_forearm"/>
		<child link="FL_foot"/>
		<axis xyz="0 1 0"/>
		<dynamics damping="0" friction="0"/>
		<limit effort="20"/>
	</joint>
	<link name="FL_foot">
		<inertial>
			<origin rpy="0 0 0" xyz="0 0 0"/>
			<mass value="0"/>
			<inertia ixx="0" ixy="0" ixz="0" iyy="0" iyz="0" izz="0"/>
		</inertial>
	</link>
	<joint name="FR_clavicle_joint" type="revolute">
		<origin rpy="0 0 0" xyz="0.25 -0.15 0"/>
		<parent link="trunk"/>
		<child link="FR_clavicle"/>
		<axis xyz="1 0 0"/>
		<dynamics damping="0" friction="0"/>
		<limit effort="20"/>
	</joint>
	<link name="FR_clavicle">
		<visual>
			<origin rpy="0 0 0" xyz="0 0 0"/>
			<geometry>
				<box size="0.1 0.04 0.1"/>
			</geometry>
			<material name="green"/>
		</visual>
		<collision>
			<origin rpy="0 0 0" xyz="0 0 0"/>
			<geometry>
				<box size="0.1 0.04 0.1"/>
			</geometry>
		</collision>
		<inertial>
			<origin rpy="0 0 0" xyz="0 0 0"/>
			<mass value="0.6"/>
			<inertia ixx="0.0005800000000000001" ixy="0" ixz="0" iyy="0.001" iyz="0" izz="0.0005800000000000001"/>
		</inertial>
	</link>
	<joint name="FR_arm_joint" type="revolute">
		<origin rpy="0 0 0" xyz="0 -0.05 0"/>
		<parent link="FR_clavicle"/>
		<child link="FR_arm"/>
		<axis xyz="0 1 0"/>
		<dynamics damping="0" friction="0"/>
		<limit effort="20"/>
	</joint>
	<link name="FR_arm">
		<visual>
			<origin rpy="0 0 0" xyz="0 0 -0.115"/>
			<geometry>
				<box size="0.04 0.02 0.23"/>
			</geometry>
			<material name="grey"/>
		</visual>
		<collision>
			<origin rpy="0 0 0" xyz="0 0 -0.115"/>
			<geometry>
				<box size="0.04 0.02 0.23"/>
			</geometry>
		</collision>
		<inertial>
			<origin rpy="0 0 0" xyz="0 0 -0.115"/>
			<mass value="0.6"/>
			<inertia ixx="0.002665" ixy="0" ixz="0" iyy="0.0027249999999999996" iyz="0" izz="9.999999999999999e-05"/>
		</inertial>
	</link>
	<joint name="FR_forearm_joint" type="revolute">
		<origin rpy="0 0 0" xyz="0 -0.03 -0.2"/>
		<parent link="FR_arm"/>
		<child link="FR_forearm"/>
		<axis xyz="0 1 0"/>
		<dynamics damping="0" friction="0"/>
		<limit effort="20"/>
	</joint>
	<link name="FR_forearm">
		<visual>
			<origin rpy="0 0 0" xyz="0 0 -0.1"/>
			<geometry>
				<box size="0.04 0.02 0.25"/>
			</geometry>
			<material name="grey"/>
		</visual>
		<collision>
			<origin rpy="0 0 0" xyz="0 0 -0.1"/>
			<geometry>
				<box size="0.04 0.02 0.25"/>
			</geometry>
		</collision>
		<inertial>
			<origin rpy="0 0 0" xyz="0 0 -0.1"/>
			<mass value="0.6"/>
			<inertia ixx="0.003145" ixy="0" ixz="0" iyy="0.003205" iyz="0" izz="9.999999999999999e-05"/>
		</inertial>
	</link>
	<joint name="FR_foot_joint" type="fixed">
		<origin rpy="0 0 0" xyz="0 -0.01 -0.25"/>
		<parent link="FR_forearm"/>
		<child link="FR_foot"/>
		<axis xyz="0 1 0"/>
		<dynamics damping="0" friction="0"/>
		<limit effort="20"/>
	</joint>
	<link name="FR_foot">
		<inertial>
			<origin rpy="0 0 0" xyz="0 0 0"/>
			<mass value="0"/>
			<inertia ixx="0" ixy="0" ixz="0" iyy="0" iyz="0" izz="0"/>
		</inertial>
	</link>
	<joint name="BL_clavicle_joint" type="revolute">
		<origin rpy="0 0 0" xyz="-0.25 0.15 0"/>
		<parent link="trunk"/>
		<child link="BL_clavicle"/>
		<axis xyz="1 0 0"/>
		<dynamics damping="0" friction="0"/>
		<limit effort="20"/>
	</joint>
	<link name="BL_clavicle">
		<visual>
			<origin rpy="0 0 0" xyz="0 0 0"/>
			<geometry>
				<box size="0.1 0.04 0.1"/>
			</geometry>
			<material name="orange"/>
		</visual>
		<collision>
			<origin rpy="0 0 0" xyz="0 0 0"/>
			<geometry>
				<box size="0.1 0.04 0.1"/>
			</geometry>
		</collision>
		<inertial>
			<origin rpy="0 0 0" xyz="0 0 0"/>
			<mass value="0.6"/>
			<inertia ixx="0.0005800000000000001" ixy="0" ixz="0" iyy="0.001" iyz="0" izz="0.0005800000000000001"/>
		</inertial>
	</link>
	<joint name="BL_arm_joint" type="revolute">
		<origin rpy="0 0 0" xyz="0 0.05 0"/>
		<parent link="BL_clavicle"/>
		<child link="BL_arm"/>
		<axis xyz="0 1 0"/>
		<dynamics damping="0" friction="0"/>
		<limit effort="20"/>
	</joint>
	<link name="BL_arm">
		<visual>
			<origin rpy="0 0 0" xyz="0 0 -0.115"/>
			<geometry>
				<box size="0.04 0.02 0.23"/>
			</geometry>
			<material name="grey"/>
		</visual>
		<collision>
			<origin rpy="0 0 0" xyz="0 0 -0.115"/>
			<geometry>
				<box size="0.04 0.02 0.23"/>
			</geometry>
		</collision>
		<inertial>
			<origin rpy="0 0 0" xyz="0 0 -0.115"/>
			<mass value="0.6"/>
			<inertia ixx="0.002665" ixy="0" ixz="0" iyy="0.0027249999999999996" iyz="0" izz="9.999999999999999e-05"/>
		</inertial>
	</link>
	<joint name="BL_forearm_joint" type="revolute">
		<origin rpy="0 0 0" xyz="0 0.03 -0.2"/>
		<parent link="BL_arm"/>
		<child link="BL_forearm"/>
		<axis xyz="0 1 0"/>
		<dynamics damping="0" friction="0"/>
		<limit effort="20"/>
	</joint>
	<link name="BL_forearm">
		<visual>
			<origin rpy="0 0 0" xyz="0 0 -0.1"/>
			<geometry>
				<box size="0.04 0.02 0.25"/>
			</geometry>
			<material name="grey"/>
		</visual>
		<collision>
			<origin rpy="0 0 0" xyz="0 0 -0.1"/>
			<geometry>
				<box size="0.04 0.02 0.25"/>
			</geometry>
		</collision>
		<inertial>
			<origin rpy="0 0 0" xyz="0 0 -0.1"/>
			<mass value="0.6"/>
			<inertia ixx="0.003145" ixy="0" ixz="0" iyy="0.003205" iyz="0" izz="9.999999999999999e-05"/>
		</inertial>
	</link>
	<joint name="BL_foot_joint" type="fixed">
		<origin rpy="0 0 0" xyz="0 0.01 -0.25"/>
		<parent link="BL_forearm"/>
		<child link="BL_foot"/>
		<axis xyz="0 1 0"/>
		<dynamics damping="0" friction="0"/>
		<limit effort="20"/>
	</joint>
	<link name="BL_foot">
		<inertial>
			<origin rpy="0 0 0" xyz="0 0 0"/>
			<mass value="0"/>
			<inertia ixx="0" ixy="0" ixz="0" iyy="0" iyz="0" izz="0"/>
		</inertial>
	</link>
	<joint name="BR_clavicle_joint" type="revolute">
		<origin rpy="0 0 0" xyz="-0.25 -0.15 0"/>
		<parent link="trunk"/>
		<child link="BR_clavicle"/>
		<axis xyz="1 0 0"/>
		<dynamics damping="0" friction="0"/>
		<limit effort="20"/>
	</joint>
	<link name="BR_clavicle">
		<visual>
			<origin rpy="0 0 0" xyz="0 0 0"/>
			<geometry>
				<box size="0.1 0.04 0.1"/>
			</geometry>
			<material name="red"/>
		</visual>
		<collision>
			<origin rpy="0 0 0" xyz="0 0 0"/>
			<geometry>
				<box size="0.1 0.04 0.1"/>
			</geometry>
		</collision>
		<inertial>
			<origin rpy="0 0 0" xyz="0 0 0"/>
			<mass value="0.6"/>
			<inertia ixx="0.0005800000000000001" ixy="0" ixz="0" iyy="0.001" iyz="0" izz="0.0005800000000000001"/>
		</inertial>
	</link>
	<joint name="BR_arm_joint" type="revolute">
		<origin rpy="0 0 0" xyz="0 -0.05 0"/>
		<parent link="BR_clavicle"/>
		<child link="BR_arm"/>
		<axis xyz="0 1 0"/>
		<dynamics damping="0" friction="0"/>
		<limit effort="20"/>
	</joint>
	<link name="BR_arm">
		<visual>
			<origin rpy="0 0 0" xyz="0 0 -0.115"/>
			<geometry>
				<box size="0.04 0.02 0.23"/>
			</geometry>
			<material name="grey"/>
		</visual>
		<collision>
			<origin rpy="0 0 0" xyz="0 0 -0.115"/>
			<geometry>
				<box size="0.04 0.02 0.23"/>
			</geometry>
		</collision>
		<inertial>
			<origin rpy="0 0 0" xyz="0 0 -0.115"/>
			<mass value="0.6"/>
			<inertia ixx="0.002665" ixy="0" ixz="0" iyy="0.0027249999999999996" iyz="0" izz="9.999999999999999e-05"/>
		</inertial>
	</link>
	<joint name="BR_forearm_joint" type="revolute">
		<origin rpy="0 0 0" xyz="0 -0.03 -0.2"/>
		<parent link="BR_arm"/>
		<child link="BR_forearm"/>
		<axis xyz="0 1 0"/>
		<dynamics damping="0" friction="0"/>
		<limit effort="20"/>
	</joint>
	<link name="BR_forearm">
		<visual>
			<origin rpy="0 0 0" xyz="0 0 -0.1"/>
			<geometry>
				<box size="0.04 0.02 0.25"/>
			</geometry>
			<material name="grey"/>
		</visual>
		<collision>
			<origin rpy="0 0 0" xyz="0 0 -0.1"/>
			<geometry>
				<box size="0.04 0.02 0.25"/>
			</geometry>
		</collision>
		<inertial>
			<origin rpy="0 0 0" xyz="0 0 -0.1"/>
			<mass value="0.6"/>
			<inertia ixx="0.003145" ixy="0" ixz="0" iyy="0.003205" iyz="0" izz="9.999999999999999e-05"/>
		</inertial>
	</link>
	<joint name="BR_foot_joint" type="fixed">
		<origin rpy="0 0 0" xyz="0 -0.01 -0.25"/>
		<parent link="BR_forearm"/>
		<child link="BR_foot"/>
		<axis xyz="0 1 0"/>
		<dynamics damping="0" friction="0"/>
		<limit effort="20"/>
	</joint>
	<link name="BR_foot">
		<inertial>
			<origin rpy="0 0 0" xyz="0 0 0"/>
			<mass value="0"/>
			<inertia ixx="0" ixy="0" ixz="0" iyy="0" iyz="0" izz="0"/>
		</inertial>
	</link>
</robot>
